Workbook

Sheet 估值模型
B2: Musk Empire Holdings
B3: MUSK
B4: Musk Empire Holdings - DCF Valuation Model
B6: 分析团队 | C6: Aurora Capital Research
B7: 报告日期 | C7: 2026-06-12
B8: 货币单位 | C8: USD
B9: 流通股数（百万） | C9: 1000
B11: 业务概览
B12: 业务板块 | C12: 描述 | D12: 营收估计
B13: Autonomy & AI | C13: Full self-driving software licensing and AI inference platform | D13: 8500
B14: EV Manufacturing | C14: Electric vehicle design, production and direct sales | D14: 12000
B15: Energy & Storage | C15: Solar panels, Powerwall, Megapack and grid-scale storage | D15: 6500
B16: Financial Services | C16: Insurance, lending and payment processing ecosystem | D16: 5000
B17: Satellite Internet | C17: Starlink LEO broadband constellation for consumer and enterprise | D17: 4200
B18: Social Media | C18: X platform advertising, subscription and data services | D18: 3000
B19: Robotics | C19: Humanoid robot (Optimus) for industrial and consumer use | D19: 1500
B20: Neural Interface | C20: Brain-computer interface technology for medical and consumer | D20: 800
B21: Underground Transport | C21: Boring Company tunnel infrastructure and loop transit systems | D21: 500
B23: 情景假设摘要
B24: 关键假设 | C24: 熊市情景 | D24: 基准情景 | E24: 牛市情景
B25: 收入CAGR | C25: ='熊市DCF'!C48 | D25: ='基准DCF'!C48 | E25: ='牛市DCF'!C48
B26: WACC | C26: ='熊市DCF'!C35 | D26: ='基准DCF'!C35 | E26: ='牛市DCF'!C35
B27: 终值增长率 | C27: ='熊市DCF'!C31 | D27: ='基准DCF'!C31 | E27: ='牛市DCF'!C31
B28: 退出倍数 | C28: ='熊市DCF'!C32 | D28: ='基准DCF'!C32 | E28: ='牛市DCF'!C32
B29: 企业价值 | C29: ='熊市DCF'!C43 | D29: ='基准DCF'!C43 | E29: ='牛市DCF'!C43
B30: 股权价值 | C30: ='熊市DCF'!C44 | D30: ='基准DCF'!C44 | E30: ='牛市DCF'!C44
B31: 每股价值 | C31: ='熊市DCF'!C45 | D31: ='基准DCF'!C45 | E31: ='牛市DCF'!C45
B32: 隐含EV/Revenue | C32: ='熊市DCF'!C46 | D32: ='基准DCF'!C46 | E32: ='牛市DCF'!C46
B33: 隐含EV/EBITDA | C33: ='熊市DCF'!C47 | D33: ='基准DCF'!C47 | E33: ='牛市DCF'!C47
B35: 跨情景估值汇总
C36: 熊市情景 | D36: 基准情景 | E36: 牛市情景
B37: 企业价值 | C37: ='熊市DCF'!C43 | D37: ='基准DCF'!C43 | E37: ='牛市DCF'!C43
B38: 净债务 | C38: ='熊市DCF'!C34 | D38: ='基准DCF'!C34 | E38: ='牛市DCF'!C34
B39: 股权价值 | C39: ='熊市DCF'!C44 | D39: ='基准DCF'!C44 | E39: ='牛市DCF'!C44
B40: 每股价值 | C40: ='熊市DCF'!C45 | D40: ='基准DCF'!C45 | E40: ='牛市DCF'!C45
B43: 免责声明：本模型仅供研究参考，不构成投资建议。

Sheet 关键运营指标
B1: 关键运营指标 / Operational KPIs
B3: 指标 | C3: 单位 | D3: 历史 (5Y) | I3: 预测 (5Y)
D4: FY21A | E4: FY22A | F4: FY23A | G4: FY24A | H4: FY25A | I4: FY26E | J4: FY27E | K4: FY28E | L4: FY29E | M4: FY30E
B5: Tesla Deliveries | C5: K units | D5: 1310 | E5: 1390 | F5: 1810 | G5: 1636 | H5: 1790 | I5: 2000 | J5: 2200 | K5: 2400 | L5: 2600 | M5: 2800
B6: Starlink Users | C6: M | D6: 2.5 | E6: 4 | F6: 6 | G6: 10.3 | H6: 15 | I6: 20 | J6: 25 | K6: 30 | L6: 35 | M6: 40
B7: SpaceX Launches | C7: Times | D7: 31 | E7: 96 | F7: 134 | G7: 180 | H7: 220 | I7: 260 | J7: 300 | K7: 340 | L7: 380 | M7: 420
B8: FSD Subscribers | C8: M | D8: 0.5 | E8: 1.2 | F8: 2.5 | G8: 5 | H8: 8 | I8: 12 | J8: 16 | K8: 20 | L8: 24 | M8: 28
B9: Optimus Units | C9: K units | D9: 0.1 | E9: 0.5 | F9: 2 | G9: 5 | H9: 10 | I9: 25 | J9: 50 | K9: 80 | L9: 120 | M9: 150

Sheet WACC拆解
B1: WACC拆解
B2: WACC拆解 | C2: 熊市情景 | D2: 基准情景 | E2: 牛市情景
B3: 股权成本(Ke) (CAPM)
B4: 无风险利率 | C4: 0.044 | D4: 0.044 | E4: 0.044
B5: 股权风险溢价 | C5: 0.055 | D5: 0.055 | E5: 0.055
B6: Beta | C6: 1.8 | D6: 1.5 | E6: 1.2
B7: 规模溢价 | C7: 0.005 | D7: 0.003 | E7: 0.002
B8: 国家风险溢价 | C8: 0 | D8: 0 | E8: 0
B9: 股权成本(Ke) | C9: =C4+C6*C5+C7+C8 | D9: =D4+D6*D5+D7+D8 | E9: =E4+E6*E5+E7+E8
B11: 债务成本(Kd)
B12: 债务成本(Kd) (Pre-tax) | C12: 0.065 | D12: 0.055 | E12: 0.045
B13: 税率 | C13: 0.21 | D13: 0.21 | E13: 0.21
B14: Kd*(1-T) | C14: =C12*(1-C13) | D14: =D12*(1-D13) | E14: =E12*(1-E13)
B16: Capital Structure
B17: 股权权重 E/(D+E) | C17: 0.9 | D17: 0.92 | E17: 0.95
B18: 债务权重 D/(D+E) | C18: =1-C17 | D18: =1-D17 | E18: =1-E17
B20: WACC | C20: =C9*C17+C14*C18 | D20: =D9*D17+D14*D18 | E20: =E9*E17+E14*E18

Sheet 熊市DCF
B1: 熊市情景
C2: FY21A | D2: FY22A | E2: FY23A | F2: FY24A | G2: FY25A | H2: FY26E | I2: FY27E | J2: FY28E | K2: FY29E | L2: FY30E
B3: 总收入
B4: Autonomy & AI | C4: 800 | D4: 1400 | E4: 2200 | F4: 3200 | G4: 4500 | H4: =4500 | I4: =H4*(1+0.0800) | J4: =I4*(1+0.0600) | K4: =J4*(1+0.0400) | L4: =K4*(1+0.0300)
B5: EV Manufacturing | C5: 2500 | D5: 3200 | E5: 4000 | F5: 5000 | G5: 5800 | H5: =5800 | I5: =H5*(1+0.0500) | J5: =I5*(1+0.0400) | K5: =J5*(1+0.0300) | L5: =K5*(1+0.0200)
B6: Energy & Storage | C6: 800 | D6: 1000 | E6: 1400 | F6: 1800 | G6: 2200 | H6: =2200 | I6: =H6*(1+0.0600) | J6: =I6*(1+0.0500) | K6: =J6*(1+0.0400) | L6: =K6*(1+0.0300)
B7: Financial Services | C7: 400 | D7: 500 | E7: 600 | F7: 800 | G7: 1000 | H7: =1000 | I7: =H7*(1+0.0500) | J7: =I7*(1+0.0400) | K7: =J7*(1+0.0300) | L7: =K7*(1+0.0200)
B8: Satellite Internet | C8: 200 | D8: 400 | E8: 800 | F8: 1400 | G8: 2000 | H8: =2000 | I8: =H8*(1+0.1200) | J8: =I8*(1+0.1000) | K8: =J8*(1+0.0800) | L8: =K8*(1+0.0600)
B9: Social Media | C9: 300 | D9: 500 | E9: 800 | F9: 1200 | G9: 1500 | H9: =1500 | I9: =H9*(1+0.0300) | J9: =I9*(1+0.0200) | K9: =J9*(1+0.0200) | L9: =K9*(1+0.0100)
B10: Robotics | C10: 50 | D10: 100 | E10: 200 | F10: 400 | G10: 700 | H10: =700 | I10: =H10*(1+0.1000) | J10: =I10*(1+0.0800) | K10: =J10*(1+0.0600) | L10: =K10*(1+0.0500)
B11: Neural Interface | C11: 30 | D11: 50 | E11: 100 | F11: 200 | G11: 400 | H11: =400 | I11: =H11*(1+0.1500) | J11: =I11*(1+0.1200) | K11: =J11*(1+0.1000) | L11: =K11*(1+0.0800)
B12: Underground Transport | C12: 20 | D12: 50 | E12: 100 | F12: 200 | G12: 300 | H12: =300 | I12: =H12*(1+0.0500) | J12: =I12*(1+0.0400) | K12: =J12*(1+0.0300) | L12: =K12*(1+0.0300)
B13: 总收入 | C13: =C4+C5+C6+C7+C8+C9+C10+C11+C12 | D13: =D4+D5+D6+D7+D8+D9+D10+D11+D12 | E13: =E4+E5+E6+E7+E8+E9+E10+E11+E12 | F13: =F4+F5+F6+F7+F8+F9+F10+F11+F12 | G13: =G4+G5+G6+G7+G8+G9+G10+G11+G12 | H13: =H4+H5+H6+H7+H8+H9+H10+H11+H12 | I13: =I4+I5+I6+I7+I8+I9+I10+I11+I12 | J13: =J4+J5+J6+J7+J8+J9+J10+J11+J12 | ... L13: =L4+L5+L6+L7+L8+L9+L10+L11+L12
B14: 营收同比增速 | D14: =IF(C13=0,0,(D13-C13)/C13) | E14: =IF(D13=0,0,(E13-D13)/D13) | F14: =IF(E13=0,0,(F13-E13)/E13) | G14: =IF(F13=0,0,(G13-F13)/F13) | H14: =IF(G13=0,0,(H13-G13)/G13) | I14: =IF(H13=0,0,(I13-H13)/H13) | J14: =IF(I13=0,0,(J13-I13)/I13) | K14: =IF(J13=0,0,(K13-J13)/J13) | L14: =IF(K13=0,0,(L13-K13)/K13)
B15: Profitability
B16: EBITDA利润率 | C16: 0.1 | D16: 0.13 | E16: 0.15 | F16: 0.16025641 | G16: 0.18 | H16: 0.18 | I16: 0.19 | J16: 0.19 | K16: 0.2 | L16: 0.2
B17: EBITDA | C17: 530 | D17: 1014 | E17: 1680 | F17: 2500 | G17: 3600 | H17: =H13*H16 | I17: =I13*I16 | J17: =J13*J16 | K17: =K13*K16 | L17: =L13*L16
B18: 折旧与摊销 | C18: =C13*0.0450 | D18: =D13*0.0450 | E18: =E13*0.0450 | F18: =F13*0.0450 | G18: =G13*0.0450 | H18: =H13*0.0450 | I18: =I13*0.0450 | J18: =J13*0.0450 | ... L18: =L13*0.0450
B19: EBIT | C19: =C17-C18 | D19: =D17-D18 | E19: =E17-E18 | F19: =F17-F18 | G19: =G17-G18 | H19: =H17-H18 | I19: =I17-I18 | J19: =J17-J18 | ... L19: =L17-L18
B20: NOPAT | C20: =C19*(1-0.2100) | D20: =D19*(1-0.2100) | E20: =E19*(1-0.2100) | F20: =F19*(1-0.2100) | G20: =G19*(1-0.2100) | H20: =H19*(1-0.2100) | I20: =I19*(1-0.2100) | J20: =J19*(1-0.2100) | ... L20: =L19*(1-0.2100)
B21: 自由现金流(UFCF)
B22: 资本支出 | C22: =C13*0.0700 | D22: =D13*0.0700 | E22: =E13*0.0700 | F22: =F13*0.0700 | G22: =G13*0.0700 | H22: =H13*0.0700 | I22: =I13*0.0700 | J22: =J13*0.0700 | ... L22: =L13*0.0700
B23: 营运资金变动 | C23: =C13*0.0600 | D23: =(D13-C13)*0.1200 | E23: =(E13-D13)*0.1200 | F23: =(F13-E13)*0.1200 | G23: =(G13-F13)*0.1200 | H23: =(H13-G13)*0.1200 | I23: =(I13-H13)*0.1200 | J23: =(J13-I13)*0.1200 | K23: =(K13-J13)*0.1200 | L23: =(L13-K13)*0.1200
B24: 自由现金流(UFCF) | C24: =C20+C18-C22-C23 | D24: =D20+D18-D22-D23 | E24: =E20+E18-E22-E23 | F24: =F20+F18-F22-F23 | G24: =G20+G18-G22-G23 | H24: =H20+H18-H22-H23 | I24: =I20+I18-I22-I23 | J24: =J20+J18-J22-J23 | ... L24: =L20+L18-L22-L23
B25: 终值
B26: 折现期 | H26: 0 | I26: 1 | J26: 2 | K26: 3 | L26: 4
B27: FCF现值 | H27: =H24/(1+0.138335)^1 | I27: =I24/(1+0.138335)^2 | J27: =J24/(1+0.138335)^3 | K27: =K24/(1+0.138335)^4 | L27: =L24/(1+0.138335)^5
B29: 关键输入参数
B30: FCF现值合计 | C30: =SUM(C27:L27)
B31: 终值增长率 | C31: 0.02
B32: 退出倍数 | C32: 8
B33: 流通股本 | C33: 1000
B34: 净债务 | C34: 5000
B35: WACC | C35: ='WACC拆解'!C20 | D35: WACC来源 → WACC拆解
B37: 终值
B38: GGM终值 | C38: =L24*(1+C31)/(C35-C31)
B39: 退出倍数终值 | C39: =L17*C32
B40: 平均终值 | C40: =(C38+C39)/2
B41: 终值现值 | C41: =C40/(1+C35)^5
B43: 企业价值 | C43: =C30+C41
...

Sheet 基准DCF
B1: 基准情景
C2: FY21A | D2: FY22A | E2: FY23A | F2: FY24A | G2: FY25A | H2: FY26E | I2: FY27E | J2: FY28E | K2: FY29E | L2: FY30E
B3: 总收入
B4: Autonomy & AI | C4: 800 | D4: 1400 | E4: 2200 | F4: 3200 | G4: 4500 | H4: =4500 | I4: =H4*(1+0.1500) | J4: =I4*(1+0.1200) | K4: =J4*(1+0.1000) | L4: =K4*(1+0.0800)
B5: EV Manufacturing | C5: 2500 | D5: 3200 | E5: 4000 | F5: 5000 | G5: 5800 | H5: =5800 | I5: =H5*(1+0.1000) | J5: =I5*(1+0.0800) | K5: =J5*(1+0.0700) | L5: =K5*(1+0.0500)
B6: Energy & Storage | C6: 800 | D6: 1000 | E6: 1400 | F6: 1800 | G6: 2200 | H6: =2200 | I6: =H6*(1+0.1200) | J6: =I6*(1+0.1000) | K6: =J6*(1+0.0800) | L6: =K6*(1+0.0700)
B7: Financial Services | C7: 400 | D7: 500 | E7: 600 | F7: 800 | G7: 1000 | H7: =1000 | I7: =H7*(1+0.1000) | J7: =I7*(1+0.0800) | K7: =J7*(1+0.0700) | L7: =K7*(1+0.0600)
B8: Satellite Internet | C8: 200 | D8: 400 | E8: 800 | F8: 1400 | G8: 2000 | H8: =2000 | I8: =H8*(1+0.2000) | J8: =I8*(1+0.1800) | K8: =J8*(1+0.1500) | L8: =K8*(1+0.1200)
B9: Social Media | C9: 300 | D9: 500 | E9: 800 | F9: 1200 | G9: 1500 | H9: =1500 | I9: =H9*(1+0.0800) | J9: =I9*(1+0.0700) | K9: =J9*(1+0.0600) | L9: =K9*(1+0.0500)
B10: Robotics | C10: 50 | D10: 100 | E10: 200 | F10: 400 | G10: 700 | H10: =700 | I10: =H10*(1+0.2500) | J10: =I10*(1+0.2000) | K10: =J10*(1+0.1500) | L10: =K10*(1+0.1200)
B11: Neural Interface | C11: 30 | D11: 50 | E11: 100 | F11: 200 | G11: 400 | H11: =400 | I11: =H11*(1+0.3000) | J11: =I11*(1+0.2500) | K11: =J11*(1+0.2000) | L11: =K11*(1+0.1500)
B12: Underground Transport | C12: 20 | D12: 50 | E12: 100 | F12: 200 | G12: 300 | H12: =300 | I12: =H12*(1+0.1000) | J12: =I12*(1+0.0800) | K12: =J12*(1+0.0700) | L12: =K12*(1+0.0600)
B13: 总收入 | C13: =C4+C5+C6+C7+C8+C9+C10+C11+C12 | D13: =D4+D5+D6+D7+D8+D9+D10+D11+D12 | E13: =E4+E5+E6+E7+E8+E9+E10+E11+E12 | F13: =F4+F5+F6+F7+F8+F9+F10+F11+F12 | G13: =G4+G5+G6+G7+G8+G9+G10+G11+G12 | H13: =H4+H5+H6+H7+H8+H9+H10+H11+H12 | I13: =I4+I5+I6+I7+I8+I9+I10+I11+I12 | J13: =J4+J5+J6+J7+J8+J9+J10+J11+J12 | ... L13: =L4+L5+L6+L7+L8+L9+L10+L11+L12
B14: 营收同比增速 | D14: =IF(C13=0,0,(D13-C13)/C13) | E14: =IF(D13=0,0,(E13-D13)/D13) | F14: =IF(E13=0,0,(F13-E13)/E13) | G14: =IF(F13=0,0,(G13-F13)/F13) | H14: =IF(G13=0,0,(H13-G13)/G13) | I14: =IF(H13=0,0,(I13-H13)/H13) | J14: =IF(I13=0,0,(J13-I13)/I13) | K14: =IF(J13=0,0,(K13-J13)/J13) | L14: =IF(K13=0,0,(L13-K13)/K13)
B15: Profitability
B16: EBITDA利润率 | C16: 0.1 | D16: 0.13 | E16: 0.15 | F16: 0.16025641 | G16: 0.18 | H16: 0.22 | I16: 0.24 | J16: 0.25 | K16: 0.26 | L16: 0.27
B17: EBITDA | C17: 530 | D17: 1014 | E17: 1680 | F17: 2500 | G17: 3600 | H17: =H13*H16 | I17: =I13*I16 | J17: =J13*J16 | K17: =K13*K16 | L17: =L13*L16
B18: 折旧与摊销 | C18: =C13*0.0350 | D18: =D13*0.0350 | E18: =E13*0.0350 | F18: =F13*0.0350 | G18: =G13*0.0350 | H18: =H13*0.0350 | I18: =I13*0.0350 | J18: =J13*0.0350 | ... L18: =L13*0.0350
B19: EBIT | C19: =C17-C18 | D19: =D17-D18 | E19: =E17-E18 | F19: =F17-F18 | G19: =G17-G18 | H19: =H17-H18 | I19: =I17-I18 | J19: =J17-J18 | ... L19: =L17-L18
B20: NOPAT | C20: =C19*(1-0.2100) | D20: =D19*(1-0.2100) | E20: =E19*(1-0.2100) | F20: =F19*(1-0.2100) | G20: =G19*(1-0.2100) | H20: =H19*(1-0.2100) | I20: =I19*(1-0.2100) | J20: =J19*(1-0.2100) | ... L20: =L19*(1-0.2100)
B21: 自由现金流(UFCF)
B22: 资本支出 | C22: =C13*0.0550 | D22: =D13*0.0550 | E22: =E13*0.0550 | F22: =F13*0.0550 | G22: =G13*0.0550 | H22: =H13*0.0550 | I22: =I13*0.0550 | J22: =J13*0.0550 | ... L22: =L13*0.0550
B23: 营运资金变动 | C23: =C13*0.0400 | D23: =(D13-C13)*0.0800 | E23: =(E13-D13)*0.0800 | F23: =(F13-E13)*0.0800 | G23: =(G13-F13)*0.0800 | H23: =(H13-G13)*0.0800 | I23: =(I13-H13)*0.0800 | J23: =(J13-I13)*0.0800 | K23: =(K13-J13)*0.0800 | L23: =(L13-K13)*0.0800
B24: 自由现金流(UFCF) | C24: =C20+C18-C22-C23 | D24: =D20+D18-D22-D23 | E24: =E20+E18-E22-E23 | F24: =F20+F18-F22-F23 | G24: =G20+G18-G22-G23 | H24: =H20+H18-H22-H23 | I24: =I20+I18-I22-I23 | J24: =J20+J18-J22-J23 | ... L24: =L20+L18-L22-L23
B25: 终值
B26: 折现期 | H26: 0 | I26: 1 | J26: 2 | K26: 3 | L26: 4
B27: FCF现值 | H27: =H24/(1+0.122616)^1 | I27: =I24/(1+0.122616)^2 | J27: =J24/(1+0.122616)^3 | K27: =K24/(1+0.122616)^4 | L27: =L24/(1+0.122616)^5
B29: 关键输入参数
B30: FCF现值合计 | C30: =SUM(C27:L27)
B31: 终值增长率 | C31: 0.03
B32: 退出倍数 | C32: 12
B33: 流通股本 | C33: 1000
B34: 净债务 | C34: 3000
B35: WACC | C35: ='WACC拆解'!D20 | D35: WACC来源 → WACC拆解
B37: 终值
B38: GGM终值 | C38: =L24*(1+C31)/(C35-C31)
B39: 退出倍数终值 | C39: =L17*C32
B40: 平均终值 | C40: =(C38+C39)/2
B41: 终值现值 | C41: =C40/(1+C35)^5
B43: 企业价值 | C43: =C30+C41
...

Sheet 牛市DCF
B1: 牛市情景
C2: FY21A | D2: FY22A | E2: FY23A | F2: FY24A | G2: FY25A | H2: FY26E | I2: FY27E | J2: FY28E | K2: FY29E | L2: FY30E
B3: 总收入
B4: Autonomy & AI | C4: 800 | D4: 1400 | E4: 2200 | F4: 3200 | G4: 4500 | H4: =4500 | I4: =H4*(1+0.2500) | J4: =I4*(1+0.2000) | K4: =J4*(1+0.1500) | L4: =K4*(1+0.1200)
B5: EV Manufacturing | C5: 2500 | D5: 3200 | E5: 4000 | F5: 5000 | G5: 5800 | H5: =5800 | I5: =H5*(1+0.1500) | J5: =I5*(1+0.1200) | K5: =J5*(1+0.1000) | L5: =K5*(1+0.0800)
B6: Energy & Storage | C6: 800 | D6: 1000 | E6: 1400 | F6: 1800 | G6: 2200 | H6: =2200 | I6: =H6*(1+0.1800) | J6: =I6*(1+0.1500) | K6: =J6*(1+0.1200) | L6: =K6*(1+0.1000)
B7: Financial Services | C7: 400 | D7: 500 | E7: 600 | F7: 800 | G7: 1000 | H7: =1000 | I7: =H7*(1+0.1500) | J7: =I7*(1+0.1200) | K7: =J7*(1+0.1000) | L7: =K7*(1+0.0800)
B8: Satellite Internet | C8: 200 | D8: 400 | E8: 800 | F8: 1400 | G8: 2000 | H8: =2000 | I8: =H8*(1+0.3000) | J8: =I8*(1+0.2500) | K8: =J8*(1+0.2000) | L8: =K8*(1+0.1500)
B9: Social Media | C9: 300 | D9: 500 | E9: 800 | F9: 1200 | G9: 1500 | H9: =1500 | I9: =H9*(1+0.1200) | J9: =I9*(1+0.1000) | K9: =J9*(1+0.0800) | L9: =K9*(1+0.0700)
B10: Robotics | C10: 50 | D10: 100 | E10: 200 | F10: 400 | G10: 700 | H10: =700 | I10: =H10*(1+0.4000) | J10: =I10*(1+0.3000) | K10: =J10*(1+0.2500) | L10: =K10*(1+0.2000)
B11: Neural Interface | C11: 30 | D11: 50 | E11: 100 | F11: 200 | G11: 400 | H11: =400 | I11: =H11*(1+0.5000) | J11: =I11*(1+0.4000) | K11: =J11*(1+0.3000) | L11: =K11*(1+0.2500)
B12: Underground Transport | C12: 20 | D12: 50 | E12: 100 | F12: 200 | G12: 300 | H12: =300 | I12: =H12*(1+0.1500) | J12: =I12*(1+0.1200) | K12: =J12*(1+0.1000) | L12: =K12*(1+0.0800)
B13: 总收入 | C13: =C4+C5+C6+C7+C8+C9+C10+C11+C12 | D13: =D4+D5+D6+D7+D8+D9+D10+D11+D12 | E13: =E4+E5+E6+E7+E8+E9+E10+E11+E12 | F13: =F4+F5+F6+F7+F8+F9+F10+F11+F12 | G13: =G4+G5+G6+G7+G8+G9+G10+G11+G12 | H13: =H4+H5+H6+H7+H8+H9+H10+H11+H12 | I13: =I4+I5+I6+I7+I8+I9+I10+I11+I12 | J13: =J4+J5+J6+J7+J8+J9+J10+J11+J12 | ... L13: =L4+L5+L6+L7+L8+L9+L10+L11+L12
B14: 营收同比增速 | D14: =IF(C13=0,0,(D13-C13)/C13) | E14: =IF(D13=0,0,(E13-D13)/D13) | F14: =IF(E13=0,0,(F13-E13)/E13) | G14: =IF(F13=0,0,(G13-F13)/F13) | H14: =IF(G13=0,0,(H13-G13)/G13) | I14: =IF(H13=0,0,(I13-H13)/H13) | J14: =IF(I13=0,0,(J13-I13)/I13) | K14: =IF(J13=0,0,(K13-J13)/J13) | L14: =IF(K13=0,0,(L13-K13)/K13)
B15: Profitability
B16: EBITDA利润率 | C16: 0.1 | D16: 0.13 | E16: 0.15 | F16: 0.16025641 | G16: 0.18 | H16: 0.25 | I16: 0.28 | J16: 0.3 | K16: 0.31 | L16: 0.32
B17: EBITDA | C17: 530 | D17: 1014 | E17: 1680 | F17: 2500 | G17: 3600 | H17: =H13*H16 | I17: =I13*I16 | J17: =J13*J16 | K17: =K13*K16 | L17: =L13*L16
B18: 折旧与摊销 | C18: =C13*0.0300 | D18: =D13*0.0300 | E18: =E13*0.0300 | F18: =F13*0.0300 | G18: =G13*0.0300 | H18: =H13*0.0300 | I18: =I13*0.0300 | J18: =J13*0.0300 | ... L18: =L13*0.0300
B19: EBIT | C19: =C17-C18 | D19: =D17-D18 | E19: =E17-E18 | F19: =F17-F18 | G19: =G17-G18 | H19: =H17-H18 | I19: =I17-I18 | J19: =J17-J18 | ... L19: =L17-L18
B20: NOPAT | C20: =C19*(1-0.2100) | D20: =D19*(1-0.2100) | E20: =E19*(1-0.2100) | F20: =F19*(1-0.2100) | G20: =G19*(1-0.2100) | H20: =H19*(1-0.2100) | I20: =I19*(1-0.2100) | J20: =J19*(1-0.2100) | ... L20: =L19*(1-0.2100)
B21: 自由现金流(UFCF)
B22: 资本支出 | C22: =C13*0.0500 | D22: =D13*0.0500 | E22: =E13*0.0500 | F22: =F13*0.0500 | G22: =G13*0.0500 | H22: =H13*0.0500 | I22: =I13*0.0500 | J22: =J13*0.0500 | ... L22: =L13*0.0500
B23: 营运资金变动 | C23: =C13*0.0300 | D23: =(D13-C13)*0.0600 | E23: =(E13-D13)*0.0600 | F23: =(F13-E13)*0.0600 | G23: =(G13-F13)*0.0600 | H23: =(H13-G13)*0.0600 | I23: =(I13-H13)*0.0600 | J23: =(J13-I13)*0.0600 | K23: =(K13-J13)*0.0600 | L23: =(L13-K13)*0.0600
B24: 自由现金流(UFCF) | C24: =C20+C18-C22-C23 | D24: =D20+D18-D22-D23 | E24: =E20+E18-E22-E23 | F24: =F20+F18-F22-F23 | G24: =G20+G18-G22-G23 | H24: =H20+H18-H22-H23 | I24: =I20+I18-I22-I23 | J24: =J20+J18-J22-J23 | ... L24: =L20+L18-L22-L23
B25: 终值
B26: 折现期 | H26: 0 | I26: 1 | J26: 2 | K26: 3 | L26: 4
B27: FCF现值 | H27: =H24/(1+0.108177)^1 | I27: =I24/(1+0.108177)^2 | J27: =J24/(1+0.108177)^3 | K27: =K24/(1+0.108177)^4 | L27: =L24/(1+0.108177)^5
B29: 关键输入参数
B30: FCF现值合计 | C30: =SUM(C27:L27)
B31: 终值增长率 | C31: 0.035
B32: 退出倍数 | C32: 16
B33: 流通股本 | C33: 1000
B34: 净债务 | C34: 1000
B35: WACC | C35: ='WACC拆解'!E20 | D35: WACC来源 → WACC拆解
B37: 终值
B38: GGM终值 | C38: =L24*(1+C31)/(C35-C31)
B39: 退出倍数终值 | C39: =L17*C32
B40: 平均终值 | C40: =(C38+C39)/2
B41: 终值现值 | C41: =C40/(1+C35)^5
B43: 企业价值 | C43: =C30+C41
...

Sheet 敏感性分析
B1: WACC × 终值增长率 → 企业价值
B2: WACC \ 终值增长率 | C2: 0.015 | D2: 0.02 | E2: 0.025 | F2: 0.03 | G2: 0.035 | H2: 0.04 | I2: 0.045
B3: 0.1026 | C3: =('基准DCF'!L24*(1+$C$2)/($B$3-$C$2)+'基准DCF'!L17*12.0)/2/(1+$B$3)^5+'基准DCF'!C30*($B$7/$B$3) | D3: =('基准DCF'!L24*(1+$D$2)/($B$3-$D$2)+'基准DCF'!L17*12.0)/2/(1+$B$3)^5+'基准DCF'!C30*($B$7/$B$3) | E3: =('基准DCF'!L24*(1+$E$2)/($B$3-$E$2)+'基准DCF'!L17*12.0)/2/(1+$B$3)^5+'基准DCF'!C30*($B$7/$B$3) | F3: =('基准DCF'!L24*(1+$F$2)/($B$3-$F$2)+'基准DCF'!L17*12.0)/2/(1+$B$3)^5+'基准DCF'!C30*($B$7/$B$3) | G3: =('基准DCF'!L24*(1+$G$2)/($B$3-$G$2)+'基准DCF'!L17*12.0)/2/(1+$B$3)^5+'基准DCF'!C30*($B$7/$B$3) | H3: =('基准DCF'!L24*(1+$H$2)/($B$3-$H$2)+'基准DCF'!L17*12.0)/2/(1+$B$3)^5+'基准DCF'!C30*($B$7/$B$3) | I3: =('基准DCF'!L24*(1+$I$2)/($B$3-$I$2)+'基准DCF'!L17*12.0)/2/(1+$B$3)^5+'基准DCF'!C30*($B$7/$B$3)
B4: 0.1076 | C4: =('基准DCF'!L24*(1+$C$2)/($B$4-$C$2)+'基准DCF'!L17*12.0)/2/(1+$B$4)^5+'基准DCF'!C30*($B$7/$B$4) | D4: =('基准DCF'!L24*(1+$D$2)/($B$4-$D$2)+'基准DCF'!L17*12.0)/2/(1+$B$4)^5+'基准DCF'!C30*($B$7/$B$4) | E4: =('基准DCF'!L24*(1+$E$2)/($B$4-$E$2)+'基准DCF'!L17*12.0)/2/(1+$B$4)^5+'基准DCF'!C30*($B$7/$B$4) | F4: =('基准DCF'!L24*(1+$F$2)/($B$4-$F$2)+'基准DCF'!L17*12.0)/2/(1+$B$4)^5+'基准DCF'!C30*($B$7/$B$4) | G4: =('基准DCF'!L24*(1+$G$2)/($B$4-$G$2)+'基准DCF'!L17*12.0)/2/(1+$B$4)^5+'基准DCF'!C30*($B$7/$B$4) | H4: =('基准DCF'!L24*(1+$H$2)/($B$4-$H$2)+'基准DCF'!L17*12.0)/2/(1+$B$4)^5+'基准DCF'!C30*($B$7/$B$4) | I4: =('基准DCF'!L24*(1+$I$2)/($B$4-$I$2)+'基准DCF'!L17*12.0)/2/(1+$B$4)^5+'基准DCF'!C30*($B$7/$B$4)
B5: 0.1126 | C5: =('基准DCF'!L24*(1+$C$2)/($B$5-$C$2)+'基准DCF'!L17*12.0)/2/(1+$B$5)^5+'基准DCF'!C30*($B$7/$B$5) | D5: =('基准DCF'!L24*(1+$D$2)/($B$5-$D$2)+'基准DCF'!L17*12.0)/2/(1+$B$5)^5+'基准DCF'!C30*($B$7/$B$5) | E5: =('基准DCF'!L24*(1+$E$2)/($B$5-$E$2)+'基准DCF'!L17*12.0)/2/(1+$B$5)^5+'基准DCF'!C30*($B$7/$B$5) | F5: =('基准DCF'!L24*(1+$F$2)/($B$5-$F$2)+'基准DCF'!L17*12.0)/2/(1+$B$5)^5+'基准DCF'!C30*($B$7/$B$5) | G5: =('基准DCF'!L24*(1+$G$2)/($B$5-$G$2)+'基准DCF'!L17*12.0)/2/(1+$B$5)^5+'基准DCF'!C30*($B$7/$B$5) | H5: =('基准DCF'!L24*(1+$H$2)/($B$5-$H$2)+'基准DCF'!L17*12.0)/2/(1+$B$5)^5+'基准DCF'!C30*($B$7/$B$5) | I5: =('基准DCF'!L24*(1+$I$2)/($B$5-$I$2)+'基准DCF'!L17*12.0)/2/(1+$B$5)^5+'基准DCF'!C30*($B$7/$B$5)
B6: 0.1176 | C6: =('基准DCF'!L24*(1+$C$2)/($B$6-$C$2)+'基准DCF'!L17*12.0)/2/(1+$B$6)^5+'基准DCF'!C30*($B$7/$B$6) | D6: =('基准DCF'!L24*(1+$D$2)/($B$6-$D$2)+'基准DCF'!L17*12.0)/2/(1+$B$6)^5+'基准DCF'!C30*($B$7/$B$6) | E6: =('基准DCF'!L24*(1+$E$2)/($B$6-$E$2)+'基准DCF'!L17*12.0)/2/(1+$B$6)^5+'基准DCF'!C30*($B$7/$B$6) | F6: =('基准DCF'!L24*(1+$F$2)/($B$6-$F$2)+'基准DCF'!L17*12.0)/2/(1+$B$6)^5+'基准DCF'!C30*($B$7/$B$6) | G6: =('基准DCF'!L24*(1+$G$2)/($B$6-$G$2)+'基准DCF'!L17*12.0)/2/(1+$B$6)^5+'基准DCF'!C30*($B$7/$B$6) | H6: =('基准DCF'!L24*(1+$H$2)/($B$6-$H$2)+'基准DCF'!L17*12.0)/2/(1+$B$6)^5+'基准DCF'!C30*($B$7/$B$6) | I6: =('基准DCF'!L24*(1+$I$2)/($B$6-$I$2)+'基准DCF'!L17*12.0)/2/(1+$B$6)^5+'基准DCF'!C30*($B$7/$B$6)
B7: 0.1226 | C7: =('基准DCF'!L24*(1+$C$2)/($B$7-$C$2)+'基准DCF'!L17*12.0)/2/(1+$B$7)^5+'基准DCF'!C30*($B$7/$B$7) | D7: =('基准DCF'!L24*(1+$D$2)/($B$7-$D$2)+'基准DCF'!L17*12.0)/2/(1+$B$7)^5+'基准DCF'!C30*($B$7/$B$7) | E7: =('基准DCF'!L24*(1+$E$2)/($B$7-$E$2)+'基准DCF'!L17*12.0)/2/(1+$B$7)^5+'基准DCF'!C30*($B$7/$B$7) | F7: =('基准DCF'!L24*(1+$F$2)/($B$7-$F$2)+'基准DCF'!L17*12.0)/2/(1+$B$7)^5+'基准DCF'!C30*($B$7/$B$7) | G7: =('基准DCF'!L24*(1+$G$2)/($B$7-$G$2)+'基准DCF'!L17*12.0)/2/(1+$B$7)^5+'基准DCF'!C30*($B$7/$B$7) | H7: =('基准DCF'!L24*(1+$H$2)/($B$7-$H$2)+'基准DCF'!L17*12.0)/2/(1+$B$7)^5+'基准DCF'!C30*($B$7/$B$7) | I7: =('基准DCF'!L24*(1+$I$2)/($B$7-$I$2)+'基准DCF'!L17*12.0)/2/(1+$B$7)^5+'基准DCF'!C30*($B$7/$B$7)
B8: 0.1276 | C8: =('基准DCF'!L24*(1+$C$2)/($B$8-$C$2)+'基准DCF'!L17*12.0)/2/(1+$B$8)^5+'基准DCF'!C30*($B$7/$B$8) | D8: =('基准DCF'!L24*(1+$D$2)/($B$8-$D$2)+'基准DCF'!L17*12.0)/2/(1+$B$8)^5+'基准DCF'!C30*($B$7/$B$8) | E8: =('基准DCF'!L24*(1+$E$2)/($B$8-$E$2)+'基准DCF'!L17*12.0)/2/(1+$B$8)^5+'基准DCF'!C30*($B$7/$B$8) | F8: =('基准DCF'!L24*(1+$F$2)/($B$8-$F$2)+'基准DCF'!L17*12.0)/2/(1+$B$8)^5+'基准DCF'!C30*($B$7/$B$8) | G8: =('基准DCF'!L24*(1+$G$2)/($B$8-$G$2)+'基准DCF'!L17*12.0)/2/(1+$B$8)^5+'基准DCF'!C30*($B$7/$B$8) | H8: =('基准DCF'!L24*(1+$H$2)/($B$8-$H$2)+'基准DCF'!L17*12.0)/2/(1+$B$8)^5+'基准DCF'!C30*($B$7/$B$8) | I8: =('基准DCF'!L24*(1+$I$2)/($B$8-$I$2)+'基准DCF'!L17*12.0)/2/(1+$B$8)^5+'基准DCF'!C30*($B$7/$B$8)
B9: 0.1326 | C9: =('基准DCF'!L24*(1+$C$2)/($B$9-$C$2)+'基准DCF'!L17*12.0)/2/(1+$B$9)^5+'基准DCF'!C30*($B$7/$B$9) | D9: =('基准DCF'!L24*(1+$D$2)/($B$9-$D$2)+'基准DCF'!L17*12.0)/2/(1+$B$9)^5+'基准DCF'!C30*($B$7/$B$9) | E9: =('基准DCF'!L24*(1+$E$2)/($B$9-$E$2)+'基准DCF'!L17*12.0)/2/(1+$B$9)^5+'基准DCF'!C30*($B$7/$B$9) | F9: =('基准DCF'!L24*(1+$F$2)/($B$9-$F$2)+'基准DCF'!L17*12.0)/2/(1+$B$9)^5+'基准DCF'!C30*($B$7/$B$9) | G9: =('基准DCF'!L24*(1+$G$2)/($B$9-$G$2)+'基准DCF'!L17*12.0)/2/(1+$B$9)^5+'基准DCF'!C30*($B$7/$B$9) | H9: =('基准DCF'!L24*(1+$H$2)/($B$9-$H$2)+'基准DCF'!L17*12.0)/2/(1+$B$9)^5+'基准DCF'!C30*($B$7/$B$9) | I9: =('基准DCF'!L24*(1+$I$2)/($B$9-$I$2)+'基准DCF'!L17*12.0)/2/(1+$B$9)^5+'基准DCF'!C30*($B$7/$B$9)
B10: 0.1376 | C10: =('基准DCF'!L24*(1+$C$2)/($B$10-$C$2)+'基准DCF'!L17*12.0)/2/(1+$B$10)^5+'基准DCF'!C30*($B$7/$B$10) | D10: =('基准DCF'!L24*(1+$D$2)/($B$10-$D$2)+'基准DCF'!L17*12.0)/2/(1+$B$10)^5+'基准DCF'!C30*($B$7/$B$10) | E10: =('基准DCF'!L24*(1+$E$2)/($B$10-$E$2)+'基准DCF'!L17*12.0)/2/(1+$B$10)^5+'基准DCF'!C30*($B$7/$B$10) | F10: =('基准DCF'!L24*(1+$F$2)/($B$10-$F$2)+'基准DCF'!L17*12.0)/2/(1+$B$10)^5+'基准DCF'!C30*($B$7/$B$10) | G10: =('基准DCF'!L24*(1+$G$2)/($B$10-$G$2)+'基准DCF'!L17*12.0)/2/(1+$B$10)^5+'基准DCF'!C30*($B$7/$B$10) | H10: =('基准DCF'!L24*(1+$H$2)/($B$10-$H$2)+'基准DCF'!L17*12.0)/2/(1+$B$10)^5+'基准DCF'!C30*($B$7/$B$10) | I10: =('基准DCF'!L24*(1+$I$2)/($B$10-$I$2)+'基准DCF'!L17*12.0)/2/(1+$B$10)^5+'基准DCF'!C30*($B$7/$B$10)
B11: 0.1426 | C11: =('基准DCF'!L24*(1+$C$2)/($B$11-$C$2)+'基准DCF'!L17*12.0)/2/(1+$B$11)^5+'基准DCF'!C30*($B$7/$B$11) | D11: =('基准DCF'!L24*(1+$D$2)/($B$11-$D$2)+'基准DCF'!L17*12.0)/2/(1+$B$11)^5+'基准DCF'!C30*($B$7/$B$11) | E11: =('基准DCF'!L24*(1+$E$2)/($B$11-$E$2)+'基准DCF'!L17*12.0)/2/(1+$B$11)^5+'基准DCF'!C30*($B$7/$B$11) | F11: =('基准DCF'!L24*(1+$F$2)/($B$11-$F$2)+'基准DCF'!L17*12.0)/2/(1+$B$11)^5+'基准DCF'!C30*($B$7/$B$11) | G11: =('基准DCF'!L24*(1+$G$2)/($B$11-$G$2)+'基准DCF'!L17*12.0)/2/(1+$B$11)^5+'基准DCF'!C30*($B$7/$B$11) | H11: =('基准DCF'!L24*(1+$H$2)/($B$11-$H$2)+'基准DCF'!L17*12.0)/2/(1+$B$11)^5+'基准DCF'!C30*($B$7/$B$11) | I11: =('基准DCF'!L24*(1+$I$2)/($B$11-$I$2)+'基准DCF'!L17*12.0)/2/(1+$B$11)^5+'基准DCF'!C30*($B$7/$B$11)
B14: WACC × 终值增长率 → 每股价值
B15: WACC \ 终值增长率 | C15: 0.015 | D15: 0.02 | E15: 0.025 | F15: 0.03 | G15: 0.035 | H15: 0.04 | I15: 0.045
B16: 0.1026 | C16: =((('基准DCF'!L24*(1+$C$15)/($B$16-$C$15)+'基准DCF'!L17*12.0)/2/(1+$B$16)^5+'基准DCF'!C30*($B$20/$B$16)-'基准DCF'!C34)/1000 | D16: =((('基准DCF'!L24*(1+$D$15)/($B$16-$D$15)+'基准DCF'!L17*12.0)/2/(1+$B$16)^5+'基准DCF'!C30*($B$20/$B$16)-'基准DCF'!C34)/1000 | E16: =((('基准DCF'!L24*(1+$E$15)/($B$16-$E$15)+'基准DCF'!L17*12.0)/2/(1+$B$16)^5+'基准DCF'!C30*($B$20/$B$16)-'基准DCF'!C34)/1000 | F16: =((('基准DCF'!L24*(1+$F$15)/($B$16-$F$15)+'基准DCF'!L17*12.0)/2/(1+$B$16)^5+'基准DCF'!C30*($B$20/$B$16)-'基准DCF'!C34)/1000 | G16: =((('基准DCF'!L24*(1+$G$15)/($B$16-$G$15)+'基准DCF'!L17*12.0)/2/(1+$B$16)^5+'基准DCF'!C30*($B$20/$B$16)-'基准DCF'!C34)/1000 | H16: =((('基准DCF'!L24*(1+$H$15)/($B$16-$H$15)+'基准DCF'!L17*12.0)/2/(1+$B$16)^5+'基准DCF'!C30*($B$20/$B$16)-'基准DCF'!C34)/1000 | I16: =((('基准DCF'!L24*(1+$I$15)/($B$16-$I$15)+'基准DCF'!L17*12.0)/2/(1+$B$16)^5+'基准DCF'!C30*($B$20/$B$16)-'基准DCF'!C34)/1000
B17: 0.1076 | C17: =((('基准DCF'!L24*(1+$C$15)/($B$17-$C$15)+'基准DCF'!L17*12.0)/2/(1+$B$17)^5+'基准DCF'!C30*($B$20/$B$17)-'基准DCF'!C34)/1000 | D17: =((('基准DCF'!L24*(1+$D$15)/($B$17-$D$15)+'基准DCF'!L17*12.0)/2/(1+$B$17)^5+'基准DCF'!C30*($B$20/$B$17)-'基准DCF'!C34)/1000 | E17: =((('基准DCF'!L24*(1+$E$15)/($B$17-$E$15)+'基准DCF'!L17*12.0)/2/(1+$B$17)^5+'基准DCF'!C30*($B$20/$B$17)-'基准DCF'!C34)/1000 | F17: =((('基准DCF'!L24*(1+$F$15)/($B$17-$F$15)+'基准DCF'!L17*12.0)/2/(1+$B$17)^5+'基准DCF'!C30*($B$20/$B$17)-'基准DCF'!C34)/1000 | G17: =((('基准DCF'!L24*(1+$G$15)/($B$17-$G$15)+'基准DCF'!L17*12.0)/2/(1+$B$17)^5+'基准DCF'!C30*($B$20/$B$17)-'基准DCF'!C34)/1000 | H17: =((('基准DCF'!L24*(1+$H$15)/($B$17-$H$15)+'基准DCF'!L17*12.0)/2/(1+$B$17)^5+'基准DCF'!C30*($B$20/$B$17)-'基准DCF'!C34)/1000 | I17: =((('基准DCF'!L24*(1+$I$15)/($B$17-$I$15)+'基准DCF'!L17*12.0)/2/(1+$B$17)^5+'基准DCF'!C30*($B$20/$B$17)-'基准DCF'!C34)/1000
B18: 0.1126 | C18: =((('基准DCF'!L24*(1+$C$15)/($B$18-$C$15)+'基准DCF'!L17*12.0)/2/(1+$B$18)^5+'基准DCF'!C30*($B$20/$B$18)-'基准DCF'!C34)/1000 | D18: =((('基准DCF'!L24*(1+$D$15)/($B$18-$D$15)+'基准DCF'!L17*12.0)/2/(1+$B$18)^5+'基准DCF'!C30*($B$20/$B$18)-'基准DCF'!C34)/1000 | E18: =((('基准DCF'!L24*(1+$E$15)/($B$18-$E$15)+'基准DCF'!L17*12.0)/2/(1+$B$18)^5+'基准DCF'!C30*($B$20/$B$18)-'基准DCF'!C34)/1000 | F18: =((('基准DCF'!L24*(1+$F$15)/($B$18-$F$15)+'基准DCF'!L17*12.0)/2/(1+$B$18)^5+'基准DCF'!C30*($B$20/$B$18)-'基准DCF'!C34)/1000 | G18: =((('基准DCF'!L24*(1+$G$15)/($B$18-$G$15)+'基准DCF'!L17*12.0)/2/(1+$B$18)^5+'基准DCF'!C30*($B$20/$B$18)-'基准DCF'!C34)/1000 | H18: =((('基准DCF'!L24*(1+$H$15)/($B$18-$H$15)+'基准DCF'!L17*12.0)/2/(1+$B$18)^5+'基准DCF'!C30*($B$20/$B$18)-'基准DCF'!C34)/1000 | I18: =((('基准DCF'!L24*(1+$I$15)/($B$18-$I$15)+'基准DCF'!L17*12.0)/2/(1+$B$18)^5+'基准DCF'!C30*($B$20/$B$18)-'基准DCF'!C34)/1000
B19: 0.1176 | C19: =((('基准DCF'!L24*(1+$C$15)/($B$19-$C$15)+'基准DCF'!L17*12.0)/2/(1+$B$19)^5+'基准DCF'!C30*($B$20/$B$19)-'基准DCF'!C34)/1000 | D19: =((('基准DCF'!L24*(1+$D$15)/($B$19-$D$15)+'基准DCF'!L17*12.0)/2/(1+$B$19)^5+'基准DCF'!C30*($B$20/$B$19)-'基准DCF'!C34)/1000 | E19: =((('基准DCF'!L24*(1+$E$15)/($B$19-$E$15)+'基准DCF'!L17*12.0)/2/(1+$B$19)^5+'基准DCF'!C30*($B$20/$B$19)-'基准DCF'!C34)/1000 | F19: =((('基准DCF'!L24*(1+$F$15)/($B$19-$F$15)+'基准DCF'!L17*12.0)/2/(1+$B$19)^5+'基准DCF'!C30*($B$20/$B$19)-'基准DCF'!C34)/1000 | G19: =((('基准DCF'!L24*(1+$G$15)/($B$19-$G$15)+'基准DCF'!L17*12.0)/2/(1+$B$19)^5+'基准DCF'!C30*($B$20/$B$19)-'基准DCF'!C34)/1000 | H19: =((('基准DCF'!L24*(1+$H$15)/($B$19-$H$15)+'基准DCF'!L17*12.0)/2/(1+$B$19)^5+'基准DCF'!C30*($B$20/$B$19)-'基准DCF'!C34)/1000 | I19: =((('基准DCF'!L24*(1+$I$15)/($B$19-$I$15)+'基准DCF'!L17*12.0)/2/(1+$B$19)^5+'基准DCF'!C30*($B$20/$B$19)-'基准DCF'!C34)/1000
B20: 0.1226 | C20: =((('基准DCF'!L24*(1+$C$15)/($B$20-$C$15)+'基准DCF'!L17*12.0)/2/(1+$B$20)^5+'基准DCF'!C30*($B$20/$B$20)-'基准DCF'!C34)/1000 | D20: =((('基准DCF'!L24*(1+$D$15)/($B$20-$D$15)+'基准DCF'!L17*12.0)/2/(1+$B$20)^5+'基准DCF'!C30*($B$20/$B$20)-'基准DCF'!C34)/1000 | E20: =((('基准DCF'!L24*(1+$E$15)/($B$20-$E$15)+'基准DCF'!L17*12.0)/2/(1+$B$20)^5+'基准DCF'!C30*($B$20/$B$20)-'基准DCF'!C34)/1000 | F20: =((('基准DCF'!L24*(1+$F$15)/($B$20-$F$15)+'基准DCF'!L17*12.0)/2/(1+$B$20)^5+'基准DCF'!C30*($B$20/$B$20)-'基准DCF'!C34)/1000 | G20: =((('基准DCF'!L24*(1+$G$15)/($B$20-$G$15)+'基准DCF'!L17*12.0)/2/(1+$B$20)^5+'基准DCF'!C30*($B$20/$B$20)-'基准DCF'!C34)/1000 | H20: =((('基准DCF'!L24*(1+$H$15)/($B$20-$H$15)+'基准DCF'!L17*12.0)/2/(1+$B$20)^5+'基准DCF'!C30*($B$20/$B$20)-'基准DCF'!C34)/1000 | I20: =((('基准DCF'!L24*(1+$I$15)/($B$20-$I$15)+'基准DCF'!L17*12.0)/2/(1+$B$20)^5+'基准DCF'!C30*($B$20/$B$20)-'基准DCF'!C34)/1000
B21: 0.1276 | C21: =((('基准DCF'!L24*(1+$C$15)/($B$21-$C$15)+'基准DCF'!L17*12.0)/2/(1+$B$21)^5+'基准DCF'!C30*($B$20/$B$21)-'基准DCF'!C34)/1000 | D21: =((('基准DCF'!L24*(1+$D$15)/($B$21-$D$15)+'基准DCF'!L17*12.0)/2/(1+$B$21)^5+'基准DCF'!C30*($B$20/$B$21)-'基准DCF'!C34)/1000 | E21: =((('基准DCF'!L24*(1+$E$15)/($B$21-$E$15)+'基准DCF'!L17*12.0)/2/(1+$B$21)^5+'基准DCF'!C30*($B$20/$B$21)-'基准DCF'!C34)/1000 | F21: =((('基准DCF'!L24*(1+$F$15)/($B$21-$F$15)+'基准DCF'!L17*12.0)/2/(1+$B$21)^5+'基准DCF'!C30*($B$20/$B$21)-'基准DCF'!C34)/1000 | G21: =((('基准DCF'!L24*(1+$G$15)/($B$21-$G$15)+'基准DCF'!L17*12.0)/2/(1+$B$21)^5+'基准DCF'!C30*($B$20/$B$21)-'基准DCF'!C34)/1000 | H21: =((('基准DCF'!L24*(1+$H$15)/($B$21-$H$15)+'基准DCF'!L17*12.0)/2/(1+$B$21)^5+'基准DCF'!C30*($B$20/$B$21)-'基准DCF'!C34)/1000 | I21: =((('基准DCF'!L24*(1+$I$15)/($B$21-$I$15)+'基准DCF'!L17*12.0)/2/(1+$B$21)^5+'基准DCF'!C30*($B$20/$B$21)-'基准DCF'!C34)/1000
B22: 0.1326 | C22: =((('基准DCF'!L24*(1+$C$15)/($B$22-$C$15)+'基准DCF'!L17*12.0)/2/(1+$B$22)^5+'基准DCF'!C30*($B$20/$B$22)-'基准DCF'!C34)/1000 | D22: =((('基准DCF'!L24*(1+$D$15)/($B$22-$D$15)+'基准DCF'!L17*12.0)/2/(1+$B$22)^5+'基准DCF'!C30*($B$20/$B$22)-'基准DCF'!C34)/1000 | E22: =((('基准DCF'!L24*(1+$E$15)/($B$22-$E$15)+'基准DCF'!L17*12.0)/2/(1+$B$22)^5+'基准DCF'!C30*($B$20/$B$22)-'基准DCF'!C34)/1000 | F22: =((('基准DCF'!L24*(1+$F$15)/($B$22-$F$15)+'基准DCF'!L17*12.0)/2/(1+$B$22)^5+'基准DCF'!C30*($B$20/$B$22)-'基准DCF'!C34)/1000 | G22: =((('基准DCF'!L24*(1+$G$15)/($B$22-$G$15)+'基准DCF'!L17*12.0)/2/(1+$B$22)^5+'基准DCF'!C30*($B$20/$B$22)-'基准DCF'!C34)/1000 | H22: =((('基准DCF'!L24*(1+$H$15)/($B$22-$H$15)+'基准DCF'!L17*12.0)/2/(1+$B$22)^5+'基准DCF'!C30*($B$20/$B$22)-'基准DCF'!C34)/1000 | I22: =((('基准DCF'!L24*(1+$I$15)/($B$22-$I$15)+'基准DCF'!L17*12.0)/2/(1+$B$22)^5+'基准DCF'!C30*($B$20/$B$22)-'基准DCF'!C34)/1000
B23: 0.1376 | C23: =((('基准DCF'!L24*(1+$C$15)/($B$23-$C$15)+'基准DCF'!L17*12.0)/2/(1+$B$23)^5+'基准DCF'!C30*($B$20/$B$23)-'基准DCF'!C34)/1000 | D23: =((('基准DCF'!L24*(1+$D$15)/($B$23-$D$15)+'基准DCF'!L17*12.0)/2/(1+$B$23)^5+'基准DCF'!C30*($B$20/$B$23)-'基准DCF'!C34)/1000 | E23: =((('基准DCF'!L24*(1+$E$15)/($B$23-$E$15)+'基准DCF'!L17*12.0)/2/(1+$B$23)^5+'基准DCF'!C30*($B$20/$B$23)-'基准DCF'!C34)/1000 | F23: =((('基准DCF'!L24*(1+$F$15)/($B$23-$F$15)+'基准DCF'!L17*12.0)/2/(1+$B$23)^5+'基准DCF'!C30*($B$20/$B$23)-'基准DCF'!C34)/1000 | G23: =((('基准DCF'!L24*(1+$G$15)/($B$23-$G$15)+'基准DCF'!L17*12.0)/2/(1+$B$23)^5+'基准DCF'!C30*($B$20/$B$23)-'基准DCF'!C34)/1000 | H23: =((('基准DCF'!L24*(1+$H$15)/($B$23-$H$15)+'基准DCF'!L17*12.0)/2/(1+$B$23)^5+'基准DCF'!C30*($B$20/$B$23)-'基准DCF'!C34)/1000 | I23: =((('基准DCF'!L24*(1+$I$15)/($B$23-$I$15)+'基准DCF'!L17*12.0)/2/(1+$B$23)^5+'基准DCF'!C30*($B$20/$B$23)-'基准DCF'!C34)/1000
B24: 0.1426 | C24: =((('基准DCF'!L24*(1+$C$15)/($B$24-$C$15)+'基准DCF'!L17*12.0)/2/(1+$B$24)^5+'基准DCF'!C30*($B$20/$B$24)-'基准DCF'!C34)/1000 | D24: =((('基准DCF'!L24*(1+$D$15)/($B$24-$D$15)+'基准DCF'!L17*12.0)/2/(1+$B$24)^5+'基准DCF'!C30*($B$20/$B$24)-'基准DCF'!C34)/1000 | E24: =((('基准DCF'!L24*(1+$E$15)/($B$24-$E$15)+'基准DCF'!L17*12.0)/2/(1+$B$24)^5+'基准DCF'!C30*($B$20/$B$24)-'基准DCF'!C34)/1000 | F24: =((('基准DCF'!L24*(1+$F$15)/($B$24-$F$15)+'基准DCF'!L17*12.0)/2/(1+$B$24)^5+'基准DCF'!C30*($B$20/$B$24)-'基准DCF'!C34)/1000 | G24: =((('基准DCF'!L24*(1+$G$15)/($B$24-$G$15)+'基准DCF'!L17*12.0)/2/(1+$B$24)^5+'基准DCF'!C30*($B$20/$B$24)-'基准DCF'!C34)/1000 | H24: =((('基准DCF'!L24*(1+$H$15)/($B$24-$H$15)+'基准DCF'!L17*12.0)/2/(1+$B$24)^5+'基准DCF'!C30*($B$20/$B$24)-'基准DCF'!C34)/1000 | I24: =((('基准DCF'!L24*(1+$I$15)/($B$24-$I$15)+'基准DCF'!L17*12.0)/2/(1+$B$24)^5+'基准DCF'!C30*($B$20/$B$24)-'基准DCF'!C34)/1000
B27: WACC × 退出倍数 → 企业价值
B28: WACC \ 退出倍数 | C28: 8 | D28: 10 | E28: 12 | F28: 14 | G28: 16
B29: 0.1026 | C29: =('基准DCF'!L24*(1+0.03)/($B$29-0.03)+'基准DCF'!L17*$C$28)/2/(1+$B$29)^5+'基准DCF'!C30*($B$33/$B$29) | D29: =('基准DCF'!L24*(1+0.03)/($B$29-0.03)+'基准DCF'!L17*$D$28)/2/(1+$B$29)^5+'基准DCF'!C30*($B$33/$B$29) | E29: =('基准DCF'!L24*(1+0.03)/($B$29-0.03)+'基准DCF'!L17*$E$28)/2/(1+$B$29)^5+'基准DCF'!C30*($B$33/$B$29) | F29: =('基准DCF'!L24*(1+0.03)/($B$29-0.03)+'基准DCF'!L17*$F$28)/2/(1+$B$29)^5+'基准DCF'!C30*($B$33/$B$29) | G29: =('基准DCF'!L24*(1+0.03)/($B$29-0.03)+'基准DCF'!L17*$G$28)/2/(1+$B$29)^5+'基准DCF'!C30*($B$33/$B$29)
B30: 0.1076 | C30: =('基准DCF'!L24*(1+0.03)/($B$30-0.03)+'基准DCF'!L17*$C$28)/2/(1+$B$30)^5+'基准DCF'!C30*($B$33/$B$30) | D30: =('基准DCF'!L24*(1+0.03)/($B$30-0.03)+'基准DCF'!L17*$D$28)/2/(1+$B$30)^5+'基准DCF'!C30*($B$33/$B$30) | E30: =('基准DCF'!L24*(1+0.03)/($B$30-0.03)+'基准DCF'!L17*$E$28)/2/(1+$B$30)^5+'基准DCF'!C30*($B$33/$B$30) | F30: =('基准DCF'!L24*(1+0.03)/($B$30-0.03)+'基准DCF'!L17*$F$28)/2/(1+$B$30)^5+'基准DCF'!C30*($B$33/$B$30) | G30: =('基准DCF'!L24*(1+0.03)/($B$30-0.03)+'基准DCF'!L17*$G$28)/2/(1+$B$30)^5+'基准DCF'!C30*($B$33/$B$30)
B31: 0.1126 | C31: =('基准DCF'!L24*(1+0.03)/($B$31-0.03)+'基准DCF'!L17*$C$28)/2/(1+$B$31)^5+'基准DCF'!C30*($B$33/$B$31) | D31: =('基准DCF'!L24*(1+0.03)/($B$31-0.03)+'基准DCF'!L17*$D$28)/2/(1+$B$31)^5+'基准DCF'!C30*($B$33/$B$31) | E31: =('基准DCF'!L24*(1+0.03)/($B$31-0.03)+'基准DCF'!L17*$E$28)/2/(1+$B$31)^5+'基准DCF'!C30*($B$33/$B$31) | F31: =('基准DCF'!L24*(1+0.03)/($B$31-0.03)+'基准DCF'!L17*$F$28)/2/(1+$B$31)^5+'基准DCF'!C30*($B$33/$B$31) | G31: =('基准DCF'!L24*(1+0.03)/($B$31-0.03)+'基准DCF'!L17*$G$28)/2/(1+$B$31)^5+'基准DCF'!C30*($B$33/$B$31)
B32: 0.1176 | C32: =('基准DCF'!L24*(1+0.03)/($B$32-0.03)+'基准DCF'!L17*$C$28)/2/(1+$B$32)^5+'基准DCF'!C30*($B$33/$B$32) | D32: =('基准DCF'!L24*(1+0.03)/($B$32-0.03)+'基准DCF'!L17*$D$28)/2/(1+$B$32)^5+'基准DCF'!C30*($B$33/$B$32) | E32: =('基准DCF'!L24*(1+0.03)/($B$32-0.03)+'基准DCF'!L17*$E$28)/2/(1+$B$32)^5+'基准DCF'!C30*($B$33/$B$32) | F32: =('基准DCF'!L24*(1+0.03)/($B$32-0.03)+'基准DCF'!L17*$F$28)/2/(1+$B$32)^5+'基准DCF'!C30*($B$33/$B$32) | G32: =('基准DCF'!L24*(1+0.03)/($B$32-0.03)+'基准DCF'!L17*$G$28)/2/(1+$B$32)^5+'基准DCF'!C30*($B$33/$B$32)
B33: 0.1226 | C33: =('基准DCF'!L24*(1+0.03)/($B$33-0.03)+'基准DCF'!L17*$C$28)/2/(1+$B$33)^5+'基准DCF'!C30*($B$33/$B$33) | D33: =('基准DCF'!L24*(1+0.03)/($B$33-0.03)+'基准DCF'!L17*$D$28)/2/(1+$B$33)^5+'基准DCF'!C30*($B$33/$B$33) | E33: =('基准DCF'!L24*(1+0.03)/($B$33-0.03)+'基准DCF'!L17*$E$28)/2/(1+$B$33)^5+'基准DCF'!C30*($B$33/$B$33) | F33: =('基准DCF'!L24*(1+0.03)/($B$33-0.03)+'基准DCF'!L17*$F$28)/2/(1+$B$33)^5+'基准DCF'!C30*($B$33/$B$33) | G33: =('基准DCF'!L24*(1+0.03)/($B$33-0.03)+'基准DCF'!L17*$G$28)/2/(1+$B$33)^5+'基准DCF'!C30*($B$33/$B$33)
B34: 0.1276 | C34: =('基准DCF'!L24*(1+0.03)/($B$34-0.03)+'基准DCF'!L17*$C$28)/2/(1+$B$34)^5+'基准DCF'!C30*($B$33/$B$34) | D34: =('基准DCF'!L24*(1+0.03)/($B$34-0.03)+'基准DCF'!L17*$D$28)/2/(1+$B$34)^5+'基准DCF'!C30*($B$33/$B$34) | E34: =('基准DCF'!L24*(1+0.03)/($B$34-0.03)+'基准DCF'!L17*$E$28)/2/(1+$B$34)^5+'基准DCF'!C30*($B$33/$B$34) | F34: =('基准DCF'!L24*(1+0.03)/($B$34-0.03)+'基准DCF'!L17*$F$28)/2/(1+$B$34)^5+'基准DCF'!C30*($B$33/$B$34) | G34: =('基准DCF'!L24*(1+0.03)/($B$34-0.03)+'基准DCF'!L17*$G$28)/2/(1+$B$34)^5+'基准DCF'!C30*($B$33/$B$34)
B35: 0.1326 | C35: =('基准DCF'!L24*(1+0.03)/($B$35-0.03)+'基准DCF'!L17*$C$28)/2/(1+$B$35)^5+'基准DCF'!C30*($B$33/$B$35) | D35: =('基准DCF'!L24*(1+0.03)/($B$35-0.03)+'基准DCF'!L17*$D$28)/2/(1+$B$35)^5+'基准DCF'!C30*($B$33/$B$35) | E35: =('基准DCF'!L24*(1+0.03)/($B$35-0.03)+'基准DCF'!L17*$E$28)/2/(1+$B$35)^5+'基准DCF'!C30*($B$33/$B$35) | F35: =('基准DCF'!L24*(1+0.03)/($B$35-0.03)+'基准DCF'!L17*$F$28)/2/(1+$B$35)^5+'基准DCF'!C30*($B$33/$B$35) | G35: =('基准DCF'!L24*(1+0.03)/($B$35-0.03)+'基准DCF'!L17*$G$28)/2/(1+$B$35)^5+'基准DCF'!C30*($B$33/$B$35)
B36: 0.1376 | C36: =('基准DCF'!L24*(1+0.03)/($B$36-0.03)+'基准DCF'!L17*$C$28)/2/(1+$B$36)^5+'基准DCF'!C30*($B$33/$B$36) | D36: =('基准DCF'!L24*(1+0.03)/($B$36-0.03)+'基准DCF'!L17*$D$28)/2/(1+$B$36)^5+'基准DCF'!C30*($B$33/$B$36) | E36: =('基准DCF'!L24*(1+0.03)/($B$36-0.03)+'基准DCF'!L17*$E$28)/2/(1+$B$36)^5+'基准DCF'!C30*($B$33/$B$36) | F36: =('基准DCF'!L24*(1+0.03)/($B$36-0.03)+'基准DCF'!L17*$F$28)/2/(1+$B$36)^5+'基准DCF'!C30*($B$33/$B$36) | G36: =('基准DCF'!L24*(1+0.03)/($B$36-0.03)+'基准DCF'!L17*$G$28)/2/(1+$B$36)^5+'基准DCF'!C30*($B$33/$B$36)
B37: 0.1426 | C37: =('基准DCF'!L24*(1+0.03)/($B$37-0.03)+'基准DCF'!L17*$C$28)/2/(1+$B$37)^5+'基准DCF'!C30*($B$33/$B$37) | D37: =('基准DCF'!L24*(1+0.03)/($B$37-0.03)+'基准DCF'!L17*$D$28)/2/(1+$B$37)^5+'基准DCF'!C30*($B$33/$B$37) | E37: =('基准DCF'!L24*(1+0.03)/($B$37-0.03)+'基准DCF'!L17*$E$28)/2/(1+$B$37)^5+'基准DCF'!C30*($B$33/$B$37) | F37: =('基准DCF'!L24*(1+0.03)/($B$37-0.03)+'基准DCF'!L17*$F$28)/2/(1+$B$37)^5+'基准DCF'!C30*($B$33/$B$37) | G37: =('基准DCF'!L24*(1+0.03)/($B$37-0.03)+'基准DCF'!L17*$G$28)/2/(1+$B$37)^5+'基准DCF'!C30*($B$33/$B$37)
B40: 情景对比汇总
B41: 关键假设 | C41: 熊市情景 | D41: 基准情景 | E41: 牛市情景
B42: 收入CAGR | C42: ='熊市DCF'!C48 | D42: ='基准DCF'!C48 | E42: ='牛市DCF'!C48
B43: WACC | C43: ='熊市DCF'!C35 | D43: ='基准DCF'!C35 | E43: ='牛市DCF'!C35
B44: 终值增长率 | C44: ='熊市DCF'!C31 | D44: ='基准DCF'!C31 | E44: ='牛市DCF'!C31
B45: 退出倍数 | C45: ='熊市DCF'!C32 | D45: ='基准DCF'!C32 | E45: ='牛市DCF'!C32
B46: 企业价值 | C46: ='熊市DCF'!C43 | D46: ='基准DCF'!C43 | E46: ='牛市DCF'!C43
...

Sheet SOTP
B1: 分部估值 / SOTP Valuation
B2: $M
B4: 业务板块 | C4: LTM收入 | D4: LTM EBITDA | E4: 估值方法 | F4: 估值倍数 | G4: 企业价值EV | H4: 备注
B5: Tesla Auto | C5: 77000 | D5: 15400 | E5: EV/EBITDA | F5: 8 | G5: =D5*F5 | H5: Comparable median
B6: SpaceX Launch | C6: 10000 | D6: 2000 | E6: EV/Revenue | F6: 15 | G6: =C6*F6 | H6: Industry avg
B7: Starlink | C7: 4200 | D7: 840 | E7: EV/Revenue | F7: 12 | G7: =C7*F7 | H7: Satellite comp median
B8: Energy & Storage | C8: 6500 | D8: 1300 | E8: EV/EBITDA | F8: 6 | G8: =D8*F8 | H8: Clean energy median
B9: X (Social Media) | C9: 3000 | D9: 600 | E9: EV/Revenue | F9: 5 | G9: =C9*F9 | H9: Social media avg
B10: Financial Services | C10: 5000 | D10: 1250 | E10: EV/EBITDA | F10: 4 | G10: =D10*F10 | H10: Fintech median
B11: Robotics (Optimus) | C11: 1500 | D11: 225 | E11: EV/Revenue | F11: 20 | G11: =C11*F11 | H11: Growth premium
B12: Neural Interface | C12: 800 | D12: 80 | E12: EV/Revenue | F12: 25 | G12: =C12*F12 | H12: Biotech premium
B13: Underground Transport | C13: 500 | D13: 100 | E13: EV/EBITDA | F13: 8 | G13: =D13*F13 | H13: Infra median
B15: 合计企业价值 | G15: =SUM(G5:G13)
B16: 减：净债务 | G16: -28000
B17: 减：少数股东权益 | G17: 0
B18: 股权价值 | G18: =G15-G16-G17
B19: 流通股本（百万） | G19: 3200
B20: 每股价值 | G20: =G18/G19

Sheet 可比公司分析
B1: 可比公司分析
B2: 美股
B3: 公司名称 | C3: 代码 | D3: 市值 | E3: 企业价值 | F3: EV/Revenue LTM | G3: EV/Revenue NTM | H3: EV/EBITDA LTM | I3: EV/EBITDA NTM | J3: 3Y CAGR | K3: 备注
B4: Tesla | C4: TSLA | D4: 800000 | E4: 750000 | F4: 5.2 | G4: 4.8 | H4: 25 | I4: 20 | J4: 0.35 | K4: Closest comp
B5: Apple | C5: AAPL | D5: 3500000 | E5: 3300000 | F5: 8 | G5: 7.5 | H5: 22 | I5: 20 | J5: 0.08 | K5: Tech ecosystem
B6: Rivian | C6: RIVN | D6: 120000 | E6: 140000 | F6: 8.5 | G6: 5.2 | H6: -25 | I6: -15 | J6: 0.55 | K6: Pre-profit
B7: XPeng | C7: XPEV | D7: 80000 | E7: 95000 | F7: 3 | G7: 2.2 | H7: -12 | I7: -6 | J7: 0.28 | K7: Tech-focused
B8: 分组中位数 (美股) | C8: =MEDIAN(C4:C7) | D8: =MEDIAN(D4:D7) | E8: =MEDIAN(E4:E7) | F8: =MEDIAN(F4:F7) | G8: =MEDIAN(G4:G7) | H8: =MEDIAN(H4:H7) | I8: =MEDIAN(I4:I7) | J8: =MEDIAN(J4:J7) | K8: =MEDIAN(K4:K7)
B10: 港股
B11: 公司名称 | C11: 代码 | D11: 市值 | E11: 企业价值 | F11: EV/Revenue LTM | G11: EV/Revenue NTM | H11: EV/EBITDA LTM | I11: EV/EBITDA NTM | J11: 3Y CAGR | K11: 备注
B12: BYD | C12: 1211.HK | D12: 950000 | E12: 880000 | F12: 1.8 | G12: 1.5 | H12: 12 | I12: 10 | J12: 0.42 | K12: China EV leader
B13: Tencent | C13: 0700.HK | D13: 450000 | E13: 420000 | F13: 4.5 | G13: 4 | H13: 18 | I13: 16 | J13: 0.1 | K13: Internet ecosystem
B14: NIO | C14: NIO | D14: 150000 | E14: 170000 | F14: 2.5 | G14: 2 | H14: -10 | I14: -5 | J14: 0.3 | K14: Premium EV
B15: 分组中位数 (港股) | C15: =MEDIAN(C12:C14) | D15: =MEDIAN(D12:D14) | E15: =MEDIAN(E12:E14) | F15: =MEDIAN(F12:F14) | G15: =MEDIAN(G12:G14) | H15: =MEDIAN(H12:H14) | I15: =MEDIAN(I12:I14) | J15: =MEDIAN(J12:J14) | K15: =MEDIAN(K12:K14)
B17: A股
B18: 公司名称 | C18: 代码 | D18: 市值 | E18: 企业价值 | F18: EV/Revenue LTM | G18: EV/Revenue NTM | H18: EV/EBITDA LTM | I18: EV/EBITDA NTM | J18: 3Y CAGR | K18: 备注
B19: BYD | C19: 002594.SZ | D19: 950000 | E19: 880000 | F19: 1.8 | G19: 1.5 | H19: 12 | I19: 10 | J19: 0.42 | K19: A-share listing
B20: CATL | C20: 300750.SZ | D20: 1100000 | E20: 1000000 | F20: 2.2 | G20: 1.8 | H20: 15 | I20: 12 | J20: 0.38 | K20: Battery leader
B21: 分组中位数 (A股) | C21: =MEDIAN(C19:C20) | D21: =MEDIAN(D19:D20) | E21: =MEDIAN(E19:E20) | F21: =MEDIAN(F19:F20) | G21: =MEDIAN(G19:G20) | H21: =MEDIAN(H19:H20) | I21: =MEDIAN(I19:I20) | J21: =MEDIAN(J19:J20) | K21: =MEDIAN(K19:K20)
B23: 中位数 | C23: =MEDIAN(C5,C6,C7,C8,C13,C14,C15,C20,C21) | D23: =MEDIAN(D5,D6,D7,D8,D13,D14,D15,D20,D21) | E23: =MEDIAN(E5,E6,E7,E8,E13,E14,E15,E20,E21) | F23: =MEDIAN(F5,F6,F7,F8,F13,F14,F15,F20,F21) | G23: =MEDIAN(G5,G6,G7,G8,G13,G14,G15,G20,G21) | H23: =MEDIAN(H5,H6,H7,H8,H13,H14,H15,H20,H21) | I23: =MEDIAN(I5,I6,I7,I8,I13,I14,I15,I20,I21) | J23: =MEDIAN(J5,J6,J7,J8,J13,J14,J15,J20,J21) | K23: =MEDIAN(K5,K6,K7,K8,K13,K14,K15,K20,K21)

Sheet PE Band
B1: 历史PE Band / Historical PE Band
B3: 当前PE | C3: 35
B4: 前瞻PE(NTM) | C4: 28
B5: 历史中位数 | C5: 55
B7: 期间 | C7: 最高 | D7: 最低 | E7: 收盘价 | F7: EPS | G7: Close PE
B8: FY2021 | C8: 120 | D8: 45 | E8: 95 | F8: 2.5 | G8: =IF(F8=0,"",E8/F8)
B9: FY2022 | C9: 100 | D9: 30 | E9: 55 | F9: 3.2 | G9: =IF(F9=0,"",E9/F9)
B10: FY2023 | C10: 80 | D10: 25 | E10: 48 | F10: 4.1 | G10: =IF(F10=0,"",E10/F10)
B11: FY2024 | C11: 70 | D11: 20 | E11: 42 | F11: 5 | G11: =IF(F11=0,"",E11/F11)
B12: FY2025 | C12: 65 | D12: 22 | E12: 38 | F12: 5.8 | G12: =IF(F12=0,"",E12/F12)
B14: 中位数 | G14: =MEDIAN(G8:G12)
B15: 平均值 | G15: =AVERAGE(G8:G12)
B16: Max | G16: =MAX(G8:G12)
B17: Min | G17: =MIN(G8:G12)
B19: 注：黄色虚线为中位数PE，红色虚线为当前PE
